<?xml version="1.0" ?>
<robot name="elebotfinal" xmlns:xacro="http://www.ros.org/wiki/xacro">

<xacro:include filename="$(find elebotfinal_description)/urdf/materials.xacro" />
<xacro:include filename="$(find elebotfinal_description)/urdf/elebotfinal.trans" />
<xacro:include filename="$(find elebotfinal_description)/urdf/elebotfinal.gazebo" />
<link name="base_link">
  <inertial>
    <origin rpy="0 0 0" xyz="0.0 0.0 0.024399999999999998"/>
    <mass value="0.03795979533447845"/>
    <inertia ixx="2e-05" ixy="0.0" ixz="0.0" iyy="4.5e-05" iyz="0.0" izz="6.5e-05"/>
  </inertial>
  <visual>
    <origin rpy="0 0 0" xyz="0 0 0"/>
    <geometry>
      <mesh filename="package://elebotfinal_description/meshes/base_link.stl" scale="0.001 0.001 0.001"/>
    </geometry>
    <material name="silver"/>
  </visual>
  <collision>
    <origin rpy="0 0 0" xyz="0 0 0"/>
    <geometry>
      <mesh filename="package://elebotfinal_description/meshes/base_link.stl" scale="0.001 0.001 0.001"/>
    </geometry>
  </collision>
</link>

<link name="right_wheel_1">
  <inertial>
    <origin rpy="0 0 0" xyz="0.0 -0.01198588004004296 2.9802316864335765e-11"/>
    <mass value="0.04129179501212183"/>
    <inertia ixx="8e-06" ixy="-0.0" ixz="0.0" iyy="1.3e-05" iyz="0.0" izz="8e-06"/>
  </inertial>
  <visual>
    <origin rpy="0 0 0" xyz="-0.0 0.025 -0.0244"/>
    <geometry>
      <mesh filename="package://elebotfinal_description/meshes/right_wheel_1.stl" scale="0.001 0.001 0.001"/>
    </geometry>
    <material name="silver"/>
  </visual>
  <collision>
    <origin rpy="0 0 0" xyz="-0.0 0.025 -0.0244"/>
    <geometry>
      <mesh filename="package://elebotfinal_description/meshes/right_wheel_1.stl" scale="0.001 0.001 0.001"/>
    </geometry>
  </collision>
</link>

<link name="left_wheel_1">
  <inertial>
    <origin rpy="0 0 0" xyz="-3.2006588430602435e-18 0.01198588004004296 2.980231339488881e-11"/>
    <mass value="0.04129179501212184"/>
    <inertia ixx="8e-06" ixy="-0.0" ixz="-0.0" iyy="1.3e-05" iyz="-0.0" izz="8e-06"/>
  </inertial>
  <visual>
    <origin rpy="0 0 0" xyz="-0.0 -0.025 -0.0244"/>
    <geometry>
      <mesh filename="package://elebotfinal_description/meshes/left_wheel_1.stl" scale="0.001 0.001 0.001"/>
    </geometry>
    <material name="silver"/>
  </visual>
  <collision>
    <origin rpy="0 0 0" xyz="-0.0 -0.025 -0.0244"/>
    <geometry>
      <mesh filename="package://elebotfinal_description/meshes/left_wheel_1.stl" scale="0.001 0.001 0.001"/>
    </geometry>
  </collision>
</link>

<link name="stand_1">
  <inertial>
    <origin rpy="0 0 0" xyz="-0.038 0.03 -0.0004000000000000045"/>
    <mass value="0.008087811245942907"/>
    <inertia ixx="1e-06" ixy="-0.0" ixz="0.0" iyy="1e-06" iyz="0.0" izz="0.0"/>
  </inertial>
  <visual>
    <origin rpy="0 0 0" xyz="-0.0 -0.0 -0.0488"/>
    <geometry>
      <mesh filename="package://elebotfinal_description/meshes/stand_1.stl" scale="0.001 0.001 0.001"/>
    </geometry>
    <material name="silver"/>
  </visual>
  <collision>
    <origin rpy="0 0 0" xyz="-0.0 -0.0 -0.0488"/>
    <geometry>
      <mesh filename="package://elebotfinal_description/meshes/stand_1.stl" scale="0.001 0.001 0.001"/>
    </geometry>
  </collision>
</link>

<link name="stand__1__1">
  <inertial>
    <origin rpy="0 0 0" xyz="-0.038 -0.03 -0.0004000000000000045"/>
    <mass value="0.008087811245942907"/>
    <inertia ixx="1e-06" ixy="-0.0" ixz="0.0" iyy="1e-06" iyz="0.0" izz="0.0"/>
  </inertial>
  <visual>
    <origin rpy="0 0 0" xyz="-0.0 -0.0 -0.0488"/>
    <geometry>
      <mesh filename="package://elebotfinal_description/meshes/stand__1__1.stl" scale="0.001 0.001 0.001"/>
    </geometry>
    <material name="silver"/>
  </visual>
  <collision>
    <origin rpy="0 0 0" xyz="-0.0 -0.0 -0.0488"/>
    <geometry>
      <mesh filename="package://elebotfinal_description/meshes/stand__1__1.stl" scale="0.001 0.001 0.001"/>
    </geometry>
  </collision>
</link>

<link name="stand__3__1">
  <inertial>
    <origin rpy="0 0 0" xyz="0.038 -0.03 -0.0004000000000000045"/>
    <mass value="0.008087811245942907"/>
    <inertia ixx="1e-06" ixy="-0.0" ixz="-0.0" iyy="1e-06" iyz="0.0" izz="0.0"/>
  </inertial>
  <visual>
    <origin rpy="0 0 0" xyz="-0.0 -0.0 -0.0488"/>
    <geometry>
      <mesh filename="package://elebotfinal_description/meshes/stand__3__1.stl" scale="0.001 0.001 0.001"/>
    </geometry>
    <material name="silver"/>
  </visual>
  <collision>
    <origin rpy="0 0 0" xyz="-0.0 -0.0 -0.0488"/>
    <geometry>
      <mesh filename="package://elebotfinal_description/meshes/stand__3__1.stl" scale="0.001 0.001 0.001"/>
    </geometry>
  </collision>
</link>

<link name="stand__2__1">
  <inertial>
    <origin rpy="0 0 0" xyz="0.038000000000000006 0.03 -0.0004000000000000045"/>
    <mass value="0.008087811245942907"/>
    <inertia ixx="1e-06" ixy="0.0" ixz="0.0" iyy="1e-06" iyz="0.0" izz="0.0"/>
  </inertial>
  <visual>
    <origin rpy="0 0 0" xyz="-0.0 -0.0 -0.0488"/>
    <geometry>
      <mesh filename="package://elebotfinal_description/meshes/stand__2__1.stl" scale="0.001 0.001 0.001"/>
    </geometry>
    <material name="silver"/>
  </visual>
  <collision>
    <origin rpy="0 0 0" xyz="-0.0 -0.0 -0.0488"/>
    <geometry>
      <mesh filename="package://elebotfinal_description/meshes/stand__2__1.stl" scale="0.001 0.001 0.001"/>
    </geometry>
  </collision>
</link>

<link name="top_plate_1">
  <inertial>
    <origin rpy="0 0 0" xyz="0.03499999999999998 -0.03 -0.020899999999999988"/>
    <mass value="0.04030789038261845"/>
    <inertia ixx="3.6e-05" ixy="-0.0" ixz="0.0" iyy="3.6e-05" iyz="0.0" izz="7.3e-05"/>
  </inertial>
  <visual>
    <origin rpy="0 0 0" xyz="0.036 -0.03 -0.0928"/>
    <geometry>
      <mesh filename="package://elebotfinal_description/meshes/top_plate_1.stl" scale="0.001 0.001 0.001"/>
    </geometry>
    <material name="silver"/>
  </visual>
  <collision>
    <origin rpy="0 0 0" xyz="0.036 -0.03 -0.0928"/>
    <geometry>
      <mesh filename="package://elebotfinal_description/meshes/top_plate_1.stl" scale="0.001 0.001 0.001"/>
    </geometry>
  </collision>
</link>

<link name="castor_1">
  <inertial>
    <origin rpy="0 0 0" xyz="0.04499999999941281 1.262829577602012e-18 -0.032428517587939666"/>
    <mass value="0.027605469171404343"/>
    <inertia ixx="1e-06" ixy="0.0" ixz="-0.0" iyy="1e-06" iyz="0.0" izz="1e-06"/>
  </inertial>
  <visual>
    <origin rpy="0 0 0" xyz="-0.0 -0.0 -0.0448"/>
    <geometry>
      <mesh filename="package://elebotfinal_description/meshes/castor_1.stl" scale="0.001 0.001 0.001"/>
    </geometry>
    <material name="silver"/>
  </visual>
  <collision>
    <origin rpy="0 0 0" xyz="-0.0 -0.0 -0.0448"/>
    <geometry>
      <mesh filename="package://elebotfinal_description/meshes/castor_1.stl" scale="0.001 0.001 0.001"/>
    </geometry>
  </collision>
</link>

<link name="breadboard_1">
  <inertial>
    <origin rpy="0 0 0" xyz="0.005556707406164164 -0.026519737726445874 -0.021624999010000007"/>
    <mass value="0.027207871222168088"/>
    <inertia ixx="6e-06" ixy="-0.0" ixz="-0.0" iyy="6e-06" iyz="-0.0" izz="1.1e-05"/>
  </inertial>
  <visual>
    <origin rpy="0 0 0" xyz="0.002 -0.0 -0.0958"/>
    <geometry>
      <mesh filename="package://elebotfinal_description/meshes/breadboard_1.stl" scale="0.001 0.001 0.001"/>
    </geometry>
    <material name="silver"/>
  </visual>
  <collision>
    <origin rpy="0 0 0" xyz="0.002 -0.0 -0.0958"/>
    <geometry>
      <mesh filename="package://elebotfinal_description/meshes/breadboard_1.stl" scale="0.001 0.001 0.001"/>
    </geometry>
  </collision>
</link>

<link name="raspberrypi__1">
  <inertial>
    <origin rpy="0 0 0" xyz="0.0040068235695858555 0.024911895152370248 -0.01926041506230225"/>
    <mass value="0.08467570456428807"/>
    <inertia ixx="2.4e-05" ixy="-1e-06" ixz="-2e-06" iyy="4.1e-05" iyz="0.0" izz="6.3e-05"/>
  </inertial>
  <visual>
    <origin rpy="0 0 0" xyz="0.002 -0.0 -0.0958"/>
    <geometry>
      <mesh filename="package://elebotfinal_description/meshes/raspberrypi__1.stl" scale="0.001 0.001 0.001"/>
    </geometry>
    <material name="silver"/>
  </visual>
  <collision>
    <origin rpy="0 0 0" xyz="0.002 -0.0 -0.0958"/>
    <geometry>
      <mesh filename="package://elebotfinal_description/meshes/raspberrypi__1.stl" scale="0.001 0.001 0.001"/>
    </geometry>
  </collision>
</link>

<link name="servo_1">
  <inertial>
    <origin rpy="0 0 0" xyz="0.007320851912220032 0.0020257004340246887 -0.01820440770709693"/>
    <mass value="0.057286092804072125"/>
    <inertia ixx="6e-06" ixy="0.0" ixz="-0.0" iyy="4e-06" iyz="1e-06" izz="4e-06"/>
  </inertial>
  <visual>
    <origin rpy="0 0 0" xyz="-0.058 -0.0 -0.0928"/>
    <geometry>
      <mesh filename="package://elebotfinal_description/meshes/servo_1.stl" scale="0.001 0.001 0.001"/>
    </geometry>
    <material name="silver"/>
  </visual>
  <collision>
    <origin rpy="0 0 0" xyz="-0.058 -0.0 -0.0928"/>
    <geometry>
      <mesh filename="package://elebotfinal_description/meshes/servo_1.stl" scale="0.001 0.001 0.001"/>
    </geometry>
  </collision>
</link>

<link name="ultrasonic_1">
  <inertial>
    <origin rpy="0 0 0" xyz="0.14852715670099287 -0.0878031941783474 -0.04207139833209038"/>
    <mass value="0.040599102302850715"/>
    <inertia ixx="7e-06" ixy="0.0" ixz="0.0" iyy="2e-06" iyz="-0.0" izz="6e-06"/>
  </inertial>
  <visual>
    <origin rpy="0 0 0" xyz="0.073781 -0.086176 -0.14296"/>
    <geometry>
      <mesh filename="package://elebotfinal_description/meshes/ultrasonic_1.stl" scale="0.001 0.001 0.001"/>
    </geometry>
    <material name="silver"/>
  </visual>
  <collision>
    <origin rpy="0 0 0" xyz="0.073781 -0.086176 -0.14296"/>
    <geometry>
      <mesh filename="package://elebotfinal_description/meshes/ultrasonic_1.stl" scale="0.001 0.001 0.001"/>
    </geometry>
  </collision>
</link>

<link name="batterypack_1">
  <inertial>
    <origin rpy="0 0 0" xyz="0.0 0.0 -0.0488"/>
    <mass value="0.0"/>
    <inertia ixx="0.0" ixy="0.0" ixz="0.0" iyy="0.0" iyz="0.0" izz="0.0"/>
  </inertial>
  <visual>
    <origin rpy="0 0 0" xyz="-0.0 -0.0 -0.0488"/>
    <geometry>
      <mesh filename="package://elebotfinal_description/meshes/batterypack_1.stl" scale="0.001 0.001 0.001"/>
    </geometry>
    <material name="silver"/>
  </visual>
  <collision>
    <origin rpy="0 0 0" xyz="-0.0 -0.0 -0.0488"/>
    <geometry>
      <mesh filename="package://elebotfinal_description/meshes/batterypack_1.stl" scale="0.001 0.001 0.001"/>
    </geometry>
  </collision>
</link>

<joint name="Rev1" type="continuous">
  <origin rpy="0 0 0" xyz="0.0 -0.025 0.0244"/>
  <parent link="base_link"/>
  <child link="right_wheel_1"/>
  <axis xyz="0.0 -1.0 0.0"/>
</joint>

<joint name="Rev2" type="continuous">
  <origin rpy="0 0 0" xyz="0.0 0.025 0.0244"/>
  <parent link="base_link"/>
  <child link="left_wheel_1"/>
  <axis xyz="0.0 1.0 0.0"/>
</joint>

<joint name="Rigid3" type="fixed">
  <origin rpy="0 0 0" xyz="0.0 0.0 0.0488"/>
  <parent link="base_link"/>
  <child link="stand_1"/>
</joint>

<joint name="Rigid4" type="fixed">
  <origin rpy="0 0 0" xyz="0.0 0.0 0.0488"/>
  <parent link="base_link"/>
  <child link="stand__1__1"/>
</joint>

<joint name="Rigid5" type="fixed">
  <origin rpy="0 0 0" xyz="0.0 0.0 0.0488"/>
  <parent link="base_link"/>
  <child link="stand__3__1"/>
</joint>

<joint name="Rigid6" type="fixed">
  <origin rpy="0 0 0" xyz="0.0 0.0 0.0488"/>
  <parent link="base_link"/>
  <child link="stand__2__1"/>
</joint>

<joint name="Rigid7" type="fixed">
  <origin rpy="0 0 0" xyz="-0.036 0.03 0.044"/>
  <parent link="stand_1"/>
  <child link="top_plate_1"/>
</joint>

<joint name="Rigid8" type="fixed">
  <origin rpy="0 0 0" xyz="0.0 0.0 0.0448"/>
  <parent link="base_link"/>
  <child link="castor_1"/>
</joint>

<joint name="Rigid9" type="fixed">
  <origin rpy="0 0 0" xyz="0.034 -0.03 0.003"/>
  <parent link="top_plate_1"/>
  <child link="breadboard_1"/>
</joint>

<joint name="Rigid10" type="fixed">
  <origin rpy="0 0 0" xyz="0.034 -0.03 0.003"/>
  <parent link="top_plate_1"/>
  <child link="raspberrypi__1"/>
</joint>

<joint name="Rigid11" type="fixed">
  <origin rpy="0 0 0" xyz="0.094 -0.03 0.0"/>
  <parent link="top_plate_1"/>
  <child link="servo_1"/>
</joint>

<joint name="Rigid12" type="fixed">
  <origin rpy="0 0 0" xyz="-0.131781 0.086176 0.05016"/>
  <parent link="servo_1"/>
  <child link="ultrasonic_1"/>
</joint>

<joint name="Rigid13" type="fixed">
  <origin rpy="0 0 0" xyz="0.0 0.0 0.0488"/>
  <parent link="base_link"/>
  <child link="batterypack_1"/>
</joint>

</robot>
